Workbook
Name _____________________________tu1: #REF!
Name ____________________________tu1: #REF!
Name ___________________________tu1: #REF!
Name __________________________tu1: #REF!
Name _________________________tu1: #REF!
Name ________________________tu1: #REF!
Name _______________________tu1: #REF!
Name ______________________tu1: #REF!
Name _____________________tu1: #REF!
Name ____________________tu1: #REF!
Name ___________________tu1: #REF!
Name __________________tu1: #REF!
Name _________________tu1: #REF!
Name ________________tu1: #REF!
Name _______________tu1: #REF!
Name ______________tu1: #REF!
Name _____________tu1: #REF!
Name ____________tu1: #REF!
Name ___________tu1: #REF!
Name __________tu1: #REF!
Name _________tu1: #REF!
Name ________tu1: #REF!
Name _______HAL12: #REF!
Name _______tu1: #REF!
Name ______HAL12: #REF!
Name ______kod1: #REF!
Name ______sum1: #REF!
Name ______tu1: #REF!
Name _____AF3: MATCH(0.01,'[1]CAPEX BE'!End_Bal,-1)+1
Name _____af4: MATCH(0.01,'[1]CAPEX BE'!End_Bal,-1)+1
Name _____ALT1: #REF!
Name _____ALT2: #REF!
Name _____ALT3: #REF!
Name _____ALT4: #REF!
Name _____ALT5: #REF!
Name _____ALT6: #REF!
Name _____ALT7: #REF!
Name _____ALT8: #REF!
Name _____ALT9: #REF!
Name _____CAD1: #REF!
Name _____DLR1: #REF!
Name _____HAL12: #REF!
Name _____KL33: #REF!
Name _____KL331: #REF!
Name _____kod1: #REF!
Name _____MEN1: #REF!
Name _____Mov2: [2]Revenue!$J$7:$R$187
Name _____PTL1: #REF!
Name _____qwe1: MATCH(0.01,'[1]CAPEX BE'!End_Bal,-1)+1
Name _____RP1: #REF!
Name _____SDM1: #REF!
Name _____sum1: #REF!
Name _____tu1: #REF!
Name _____z2: MATCH(0.01,'[1]CAPEX BE'!End_Bal,-1)+1
Name ____DLR1: #REF!
Name ____HAL12: #REF!
Name ____kii44: #REF!
Name ____kod1: #REF!
Name ____MNP0205: #REF!
Name ____Mov2: [2]Revenue!$J$7:$R$187

Sheet Model Design
B2: MODEL DESIGN — PT JAMINAN PEMBIAYAAN ASKRINDO SYARIAH
B3: Financial Performance Workbook | Periode Mei 2026 | CFI-Standard Model Design Framework
B4: CONFIDENTIAL — Internal Use Only
B6: 1. MODEL OBJECTIVE (Output-First Design)
B7: Decision This Model Answers: | C7: How is JPAS performing against RKAP 2026, and what are the key risk drivers affecting profitability?
B8: Primary Audience: | C8: Management / Komisaris / OJK Reporting
B9: Periodicity: | C9: Monthly (YTD actuals vs. RKAP budget)
B10: Currency & Units: | C10: IDR in Jutaan Rupiah (Rp Juta)
B12: 2. MODEL CHECKS (Display on Cover)
B13: Check | C13: Formula / Source | D13: Status
B14: Balance Sheet Balanced? | C14: = Total Aset − (Total Liabilitas + Total Ekuitas) = 0 | D14: → Link from Summary BS KONSOL
B15: Laba Rugi ties to Ekuitas (BS)? | C15: = Laba Neto in IS = Perubahan Retained Earnings in BS | D15: → Verify cross-statement link
B16: Cash Flow ties to Kas (BS)? | C16: = Ending Cash in CFS = Kas & Setara Kas in BS | D16: → Link from CASH FLOW Mei 2026
B17: RKAP Utilization Within Limit? | C17: = YTD Realisasi / RKAP s/d Period ≤ 100% | D17: → Flag if >100% (overspend)
B18: Gearing Ratio Within Limit? | C18: = As per OJK/regulatory threshold (typical: ≤40x) | D18: → Link from Gearing Ratio sheet
B20: 3. MODULAR BUILDING BLOCKS — TAB INVENTORY
B21: Block Type | C21: Tab Name | D21: Purpose | E21: Feeds Into
B22: COVER / DESIGN | C22: Model Design (this sheet) | D22: Objective, checks, tab map, driver framework | E22: —
B23: DASHBOARD / OUTPUT | C23: Lap. LR-Kinerja Mei 2026 | D23: Comprehensive P&L performance vs. RKAP & prior year | E23: Management report
B24: DASHBOARD / OUTPUT | C24: Lap. PK - Kinerja Mei 2026 | D24: Balance sheet performance KPIs | E24: Management report
B25: DASHBOARD / OUTPUT | C25: Lap. AK-Kinerja Mei 2026 | D25: Cash flow & liquidity KPIs | E25: Management report
B26: FINANCIAL STATEMENT | C26: Summary PL KONSOL Mei 2026 | D26: Consolidated P&L: YTD, MoM, YoY, vs. RKAP | E26: Lap. LR-Kinerja; Dashboard
B27: FINANCIAL STATEMENT | C27: Summary BS KONSOL Mei 2026 | D27: Consolidated balance sheet | E27: Lap. PK-Kinerja; BS Check
B28: FINANCIAL STATEMENT | C28: CASH FLOW Mei 2026 | D28: Operating / Investing / Financing cash flows | E28: Lap. AK-Kinerja; Cash Check
B29: OPERATING SCHEDULE | C29: Hasil Underwriting | D29: Underwriting result: IJK, claims, net UW income | E29: Summary PL KONSOL
B30: OPERATING SCHEDULE | C30: Input HUW | D30: Raw underwriting input assumptions / data entry | E30: Hasil Underwriting
B31: OPERATING SCHEDULE | C31: Cadangan Teknis | D31: Technical reserves (IBNR, unearned premium equiv.) | E31: Summary BS; Summary PL
B32: OPERATING SCHEDULE | C32: Beban Usaha | D32: Operating expense detail by line item | E32: Summary PL KONSOL; Opex
... B46: BUSINESS VOLUME | C46: KUR | D46: KUR (Kredit Usaha Rakyat) program volume & performance | E46: Hasil Underwriting; Summary PL
B48: 4. KEY DRIVERS — Volatile & High-Impact Inputs
B49: Driver | C49: Volatile? | D49: High Impact? | E49: Is a Driver? | F49: Source Tab
B50: Imbal Jasa Kafalah (IJK) volume | C50: YES | D50: YES | E50: ✓ DRIVER | F50: Input HUW; Per Bank Per COB
B51: Klaim / Tawidh rate (loss ratio) | C51: YES | D51: YES | E51: ✓ DRIVER | F51: Hasil Underwriting; Cadangan Teknis
B52: Beban penjaminan ulang (re-kafalah cost) | C52: Moderate | D52: YES | E52: ✓ DRIVER | F52: Input HUW; Summary PL
B53: Cadangan teknis (IBNR / unearned) | C53: YES | D53: YES | E53: ✓ DRIVER | F53: Cadangan Teknis
B54: Investment return (yield on portfolio) | C54: Moderate | D54: YES | E54: ✓ DRIVER | F54: Investasi Mei 2026
B55: Opex / Beban usaha total | C55: Moderate | D55: Moderate | E55: ✓ DRIVER | F55: Beban Usaha; Opex
B56: Gearing ratio (regulatory limit) | C56: YES | D56: YES | E56: ✓ DRIVER | F56: Gearing Ratio
B57: Tax rate | C57: NO | D57: Moderate | E57: — Not a driver | F57: Stable per regulation
B58: Subrogasi recovery rate | C58: YES | D58: LOW | E58: — Monitor only | F58: Subrogasi + SHS
...

Sheet Summary PL KONSOL Mei 2026
A1: Laporan Laba Rugi Konsolidasi Askrindo dan Entitas Anak
A2: (dalam Jutaan Rupiah)
A3: Keterangan | D3: Realisasi | F3: Realisasi | H3: Realisasi | J3: %YoY | L3: Realisasi | N3: Realisasi | P3: %MoM | R3: RKAP s/d Mei 2026 | T3: % terhadap RKAP s/d Januari 2026 | V3: RKAP 2026 | X3: % terhadap RKAP 2026
D4: s/d April 2026 | F4: s/d Mei 2026 | H4: s/d Mei 2025 | L4: April 2026 | N4: Mei 2026
A6: Pendapatan Underwriting | D6: 208154.21 | E6: =SUM(E8:E12) | F6: =SUM(F8:F12) | H6: 212565.69 | J6: =F6/H6-1 | L6: 57323.966 | N6: =F6-D6 | P6: =N6/L6-1 | R6: =SUM(R8:R12) | T6: =F6/R6 | V6: =SUM(V8:V12) | X6: =F6/V6
D7: 0 | F7: =N7 | H7: 0 | L7: 0 | N7: 0
A8: Pendapatan Jasa Penjaminan (IJK) | D8: 328122.62 | F8: ='Lap. LR-Kinerja Mei 2026'!F9 | H8: 283047.36 | J8: =F8/H8-1 | L8: 78485.329 | N8: =F8-D8 | P8: =N8/L8-1 | R8: 361609.38 | T8: =F8/R8 | V8: ='Lap. LR-Kinerja Mei 2026'!E9 | X8: =F8/V8
A9: Beban Penjaminan Ulang | D9: -79897.189 | F9: ='Lap. LR-Kinerja Mei 2026'!F11 | H9: -72165.752 | J9: =F9/H9-1 | L9: -18445.639 | N9: =F9-D9 | P9: =N9/L9-1 | R9: -94444.697 | T9: =F9/R9 | V9: ='Lap. LR-Kinerja Mei 2026'!E11 | X9: =F9/V9
A10: Komisi penjaminan ulang | D10: 22277.016 | F10: ='Lap. LR-Kinerja Mei 2026'!F12+'Lap. LR-Kinerja Mei 2026'!F13 | H10: 25400.057 | J10: =F10/H10-1 | L10: 5896.4258 | N10: =F10-D10 | P10: =N10/L10-1 | R10: 19643.534 | T10: =F10/R10 | V10: ='Lap. LR-Kinerja Mei 2026'!E12+'Lap. LR-Kinerja Mei 2026'!E13 | X10: =F10/V10
A11: (Kenaikan) Penurunan IJK yang Belum Merupakan Pendapatan | D11: -62379.684 | F11: ='Lap. LR-Kinerja Mei 2026'!F14 | H11: -23756.249 | J11: =F11/H11-1 | L11: -8619.8818 | N11: =F11-D11 | P11: =N11/L11-1 | R11: -38853.236 | T11: =F11/R11 | V11: ='Lap. LR-Kinerja Mei 2026'!E14 | X11: =F11/V11
A12: Pendapatan Underwriting Lain | D12: 31.448552 | F12: ='Lap. LR-Kinerja Mei 2026'!F15 | H12: 40.273 | J12: 0 | L12: 7.732 | N12: =F12-D12 | P12: =N12/L12-1 | R12: 54.460224 | T12: =F12/R12 | V12: ='Lap. LR-Kinerja Mei 2026'!E15 | X12: =F12/V12
A14: Beban Underwriting | D14: 138400.76 | F14: =SUM(F16:F22) | H14: 112554.02 | J14: =F14/H14-1 | L14: 27550.756 | N14: =F14-D14 | P14: =N14/L14-1 | R14: =SUM(R16:R22) | T14: =F14/R14 | V14: =SUM(V16:V22) | X14: =F14/V14
A16: Ta'widh Bruto | D16: 188989.84 | F16: ='Lap. LR-Kinerja Mei 2026'!F19 | H16: 156690.22 | J16: =F16/H16-1 | L16: 42288.658 | N16: =F16-D16 | P16: =N16/L16-1 | R16: 208980.21 | T16: =F16/R16 | V16: ='Lap. LR-Kinerja Mei 2026'!E19 | X16: =F16/V16
A17: Ta'widh Reasuransi | D17: -60256.244 | F17: ='Lap. LR-Kinerja Mei 2026'!F20 | H17: -52659.469 | J17: =F17/H17-1 | L17: -13833.969 | N17: =F17-D17 | P17: =N17/L17-1 | R17: -67864.798 | T17: =F17/R17 | V17: ='Lap. LR-Kinerja Mei 2026'!E20 | X17: =F17/V17
A18: Kenaikan (Penurunan) Estimasi Tawidh Retensi Sendiri | D18: 19968.458 | F18: ='Lap. LR-Kinerja Mei 2026'!F24 | H18: 40617.292 | J18: =F18/H18-1 | L18: 1868.4391 | N18: =F18-D18 | P18: =N18/L18-1 | R18: 21007.135 | T18: =F18/R18 | V18: ='Lap. LR-Kinerja Mei 2026'!E24 | X18: =F18/V18
A19: Pendapatan Recoveries - bersih | D19: -19650.767 | F19: ='Lap. LR-Kinerja Mei 2026'!F23 | H19: -40708.37 | J19: =F19/H19-1 | L19: -5277.2595 | N19: =F19-D19 | P19: =N19/L19-1 | R19: -18524.823 | T19: =F19/R19 | V19: ='Lap. LR-Kinerja Mei 2026'!E23 | X19: =F19/V19
A20: Beban Komisi | D20: 10932.712 | F20: ='Lap. LR-Kinerja Mei 2026'!F21 | H20: 7854.2954 | J20: =F20/H20-1 | L20: 1564.806 | N20: =F20-D20 | P20: =N20/L20-1 | R20: 11804.442 | T20: =F20/R20 | V20: ='Lap. LR-Kinerja Mei 2026'!E21 | X20: =F20/V20
A21: Beban akuisisi tangguhan | D21: -2283.2809 | F21: ='Lap. LR-Kinerja Mei 2026'!F22 | H21: -134.76586 | J21: =F21/H21-1 | L21: 882.38976 | N21: =F21-D21 | P21: =N21/L21-1 | R21: -1444.2408 | T21: =F21/R21 | V21: ='Lap. LR-Kinerja Mei 2026'!E22 | X21: =F21/V21
A22: Beban Underwriting Lain | D22: 700.04037 | F22: ='Lap. LR-Kinerja Mei 2026'!F25 | H22: 894.81787 | J22: =F22/H22-1 | L22: 57.69153 | N22: =F22-D22 | P22: =IFERROR(N22/L22-1,"") | R22: 1294.8414 | T22: =F22/R22 | V22: ='Lap. LR-Kinerja Mei 2026'!E25 | X22: =F22/V22
A24: Hasil Underwriting Neto | D24: 69753.455 | F24: =F6-F14 | H24: 100011.67 | J24: =F24/H24-1 | L24: 29773.21 | N24: =F24-D24 | P24: =N24/L24-1 | R24: =R6-R14 | T24: =F24/R24 | V24: =V6-V14 | X24: =F24/V24
A26: Hasil Investasi | D26: 50162.338 | F26: ='Lap. LR-Kinerja Mei 2026'!F29 | H26: 59202.376 | J26: =F26/H26-1 | L26: 12425.926 | N26: =F26-D26 | P26: =N26/L26-1 | R26: 63701.826 | T26: =F26/R26 | V26: ='Lap. LR-Kinerja Mei 2026'!E29 | X26: =F26/V26
A28: Beban Pemasaran | D28: 4349.7301 | F28: ='Lap. LR-Kinerja Mei 2026'!F32 | H28: 4712.1651 | J28: =F28/H28-1 | L28: 1082.7826 | N28: =F28-D28 | P28: =N28/L28-1 | R28: 5808.4799 | T28: =F28/R28 | V28: ='Lap. LR-Kinerja Mei 2026'!E32 | X28: =F28/V28
A29: Beban Umum | D29: 34312.458 | F29: ='Lap. LR-Kinerja Mei 2026'!F33 | H29: 39671.097 | J29: =F29/H29-1 | L29: 10307.703 | N29: =F29-D29 | P29: =N29/L29-1 | R29: 47265.863 | T29: =F29/R29 | V29: ='Lap. LR-Kinerja Mei 2026'!E33 | X29: =F29/V29
A30: Beban Administrasi | D30: 5846.7861 | F30: ='Lap. LR-Kinerja Mei 2026'!F34 | H30: 7210.0197 | J30: =F30/H30-1 | L30: 1807.035 | N30: =F30-D30 | P30: =N30/L30-1 | R30: 10296.714 | T30: =F30/R30 | V30: ='Lap. LR-Kinerja Mei 2026'!E34 | X30: =F30/V30
A31: Beban Penyusutan & Amortasi | D31: 4728.0455 | F31: ='Lap. LR-Kinerja Mei 2026'!F35 | H31: 6389.3085 | J31: =F31/H31-1 | L31: 1234.7307 | N31: =F31-D31 | P31: =N31/L31-1 | R31: 6639.2721 | T31: =F31/R31 | V31: ='Lap. LR-Kinerja Mei 2026'!E35 | X31: =F31/V31
A32: Total Beban Usaha | D32: 49237.019 | E32: =SUM(E28:E31) | F32: =SUM(F28:F31) | G32: =SUM(G28:G31) | H32: 57982.591 | J32: =F32/H32-1 | L32: 14432.252 | M32: =SUM(M28:M31) | N32: =F32-D32 | P32: =N32/L32-1 | R32: 70010.329 | T32: =F32/R32 | V32: =SUM(V28:V31) | X32: =F32/V32
A34: Laba Usaha | D34: 70678.775 | F34: =F24+F26-F32 | H34: 101231.46 | J34: =F34/H34-1 | L34: 27766.884 | N34: =F34-D34 | P34: =N34/L34-1 | R34: =R24+R26-R32 | T34: =F34/R34 | V34: =(V24+V26)-V32 | X34: =F34/V34
A36: (Beban) Pendapatan Lain-lain | D36: -6495.4726 | F36: ='Lap. LR-Kinerja Mei 2026'!F40 | H36: -7016.9091 | J36: =F36/H36-1 | L36: -1751.0852 | N36: =F36-D36 | P36: =N36/L36-1 | R36: -7879.2136 | T36: =F36/R36 | V36: ='Lap. LR-Kinerja Mei 2026'!E40 | X36: =F36/V36
A38: Zakat | D38: 1604.5825 | F38: ='Lap. LR-Kinerja Mei 2026'!F44 | H38: 2355.3637 | J38: =F38/H38-1 | L38: 650.39498 | N38: =F38-D38 | P38: =N38/L38-1 | R38: 1964.2239 | T38: =F38/R38 | V38: ='Lap. LR-Kinerja Mei 2026'!E44 | X38: =F38/V38
A40: Laba Sebelum Pajak | D40: 62578.719 | F40: =F34+F36-F38 | H40: 91859.182 | J40: =F40/H40-1 | L40: 25365.404 | N40: =F40-D40 | P40: =N40/L40-1 | R40: 76604.734 | T40: =F40/R40 | V40: =V34+V36-V38 | X40: =F40/V40
A42: Pajak Penghasilan | D42: 11552.994 | F42: ='Lap. LR-Kinerja Mei 2026'!F50 | H42: 15074.327 | J42: =F42/H42-1 | L42: 4797.3463 | N42: =F42-D42 | P42: =N42/L42-1 | R42: 14554.899 | T42: =F42/R42 | V42: ='Lap. LR-Kinerja Mei 2026'!E50 | X42: =F42/V42
A44: Laba Setelah Pajak | D44: 51025.725 | F44: =F40-F42 | H44: 76784.855 | J44: =F44/H44-1 | L44: 20568.058 | N44: =F44-D44 | P44: =N44/L44-1 | R44: 62049.835 | T44: =F44/R44 | V44: =V40-V42 | X44: =F44/V44

Sheet Summary BS KONSOL Mei 2026
A1: Laporan Posisi Keuangan Konsolidasi Askrindo dan Entitas Anak
A2: (dalam Jutaan Rupiah)
A3: Keterangan | D3: Realisasi | F3: Realisasi | H3: Audited | I3: Realisasi | K3: %YoY | M3: Realisasi | O3: Realisasi | Q3: %MoM | S3: RKAP s/d Mei 2026 | U3: % terhadap RKAP s/d Mei 2026 | W3: RKAP 2026 | Y3: % terhadap RKAP 2026
D4: Per April 2026 | F4: Per Mei 2026 | H4: s/d Mei '22 | I4: Per Mei 2025 | M4: April 2026 | O4: Mei 2026
A6: ASET | D6: 3403950.7 | F6: =SUM(F8:F23) | I6: 3193491.6 | K6: =F6/I6-1 | M6: 64843.671 | O6: =SUM(O8:O24) | Q6: =IFERROR((O6/M6-1),"") | S6: =SUM(S8:S23) | U6: =IFERROR(F6/S6,"") | W6: =SUM(W8:W23) | Y6: =IFERROR(F6/W6,"")
Q7: =IFERROR((O7/M7-1),"") | U7: =IFERROR(F7/S7,"") | Y7: =IFERROR(F7/W7,"")
A8: Kas dan bank | D8: 81962.748 | F8: ='Lap. PK - Kinerja Mei 2026'!E11+'Lap. PK - Kinerja Mei 2026'!E12 | I8: 117308.06 | K8: =IFERROR(F8/I8-1,"") | M8: -1299.8155 | O8: =F8-D8 | Q8: =IFERROR((O8/M8-1),"") | S8: 111761.85 | U8: =IFERROR(F8/S8,"") | W8: 120923.64 | Y8: =IFERROR(F8/W8,"")
A9: Piutang imbal jasa kafalah | D9: 2006.4061 | F9: ='Lap. PK - Kinerja Mei 2026'!E13+'Lap. PK - Kinerja Mei 2026'!E14 | I9: 2831.5346 | K9: =IFERROR(F9/I9-1,"") | M9: 543.38737 | O9: =F9-D9 | Q9: =IFERROR((O9/M9-1),"") | S9: 2723.466 | U9: =IFERROR(F9/S9,"") | W9: 2959.6378 | Y9: =IFERROR(F9/W9,"")
A10: Piutang ta'widh | D10: 76504.003 | F10: ='Lap. PK - Kinerja Mei 2026'!E15+'Lap. PK - Kinerja Mei 2026'!E16 | I10: 43262.629 | K10: =IFERROR(F10/I10-1,"") | M10: 12409.392 | O10: =F10-D10 | Q10: =IFERROR((O10/M10-1),"") | S10: 58047.528 | U10: =IFERROR(F10/S10,"") | W10: 56682.869 | Y10: =IFERROR(F10/W10,"")
A11: Piutang investasi | D11: 34359.264 | F11: ='Lap. PK - Kinerja Mei 2026'!E17 | I11: 25479.052 | K11: =IFERROR(F11/I11-1,"") | M11: 3479.7919 | O11: =F11-D11 | Q11: =IFERROR((O11/M11-1),"") | S11: 29857.589 | U11: =IFERROR(F11/S11,"") | W11: 31921.341 | Y11: =IFERROR(F11/W11,"")
A12: Aset Reasuransi | D12: 653784.3 | F12: ='Lap. PK - Kinerja Mei 2026'!E18 | I12: 724218.71 | K12: =IFERROR(F12/I12-1,"") | M12: 15763.458 | O12: =F12-D12 | Q12: =IFERROR((O12/M12-1),"") | S12: 768023.6 | U12: =IFERROR(F12/S12,"") | W12: 847155.3 | Y12: =IFERROR(F12/W12,"")
A13: Biaya akuisisi yang ditangguhkan | D13: 38412.166 | F13: ='Lap. PK - Kinerja Mei 2026'!E19 | I13: 34915.418 | K13: =IFERROR(F13/I13-1,"") | M13: -882.38976 | O13: =F13-D13 | Q13: =IFERROR((O13/M13-1),"") | S13: 35488.632 | U13: =IFERROR(F13/S13,"") | W13: 37638.341 | Y13: =IFERROR(F13/W13,"")
A14: Biaya dibayar dimuka | D14: 13719.294 | F14: ='Lap. PK - Kinerja Mei 2026'!E20 | I14: 12088.355 | K14: =IFERROR(F14/I14-1,"") | M14: 123.77778 | O14: =F14-D14 | Q14: =IFERROR((O14/M14-1),"") | S14: 11998.819 | U14: =IFERROR(F14/S14,"") | W14: 11888.738 | Y14: =IFERROR(F14/W14,"")
A15: Pajak dibayar dimuka | D15: 1.9073486e-11 | F15: ='Lap. PK - Kinerja Mei 2026'!E21 | I15: 1.9073486e-11 | K15: =IFERROR(F15/I15-1,"") | M15: 0 | O15: =F15-D15 | Q15: =IFERROR((O15/M15-1),"") | S15: 0 | U15: =IFERROR(F15/S15,"") | W15: 0 | Y15: =IFERROR(F15/W15,"")
A16: Investasi | K16: =IFERROR(F16/I16-1,"")
A17: Deposito berjangka mudharabah | D17: 432300 | F17: ='Lap. PK - Kinerja Mei 2026'!E23 | I17: 467050 | K17: =IFERROR(F17/I17-1,"") | M17: -114900 | O17: =F17-D17 | Q17: =IFERROR((O17/M17-1),"") | S17: 454400 | U17: =IFERROR(F17/S17,"") | W17: 454400 | Y17: =IFERROR(F17/W17,"")
A18: Reksadana tersedia untuk dijual | D18: 100625.15 | F18: ='Lap. PK - Kinerja Mei 2026'!E24 | I18: 80748.598 | K18: =IFERROR(F18/I18-1,"") | M18: 44987.618 | O18: =F18-D18 | Q18: =IFERROR((O18/M18-1),"") | S18: 127056.67 | U18: =IFERROR(F18/S18,"") | W18: 142246.67 | Y18: =IFERROR(F18/W18,"")
A19: Surat Berharga Syariah Negara | D19: 1916908.5 | F19: ='Lap. PK - Kinerja Mei 2026'!E25 | I19: 1636665 | K19: =IFERROR(F19/I19-1,"") | M19: 96209.504 | O19: =F19-D19 | Q19: =IFERROR((O19/M19-1),"") | S19: 1887212.7 | U19: =IFERROR(F19/S19,"") | W19: 2034233.9 | Y19: =IFERROR(F19/W19,"")
A20: Aset pajak tangguhan | D20: 22839.203 | F20: ='Lap. PK - Kinerja Mei 2026'!E26 | I20: 13872.599 | K20: =IFERROR(F20/I20-1,"") | M20: 8966.6037 | O20: =F20-D20 | Q20: =IFERROR((O20/M20-1),"") | S20: 13872.599 | U20: =IFERROR(F20/S20,"") | W20: 13872.599 | Y20: =IFERROR(F20/W20,"")
A21: Aset tetap | D21: 26990.454 | F21: ='Lap. PK - Kinerja Mei 2026'!E27 | I21: 30460.163 | K21: =IFERROR(F21/I21-1,"") | M21: -476.74334 | O21: =F21-D21 | Q21: =IFERROR((O21/M21-1),"") | S21: 32231.263 | U21: =IFERROR(F21/S21,"") | W21: 26433.967 | Y21: =IFERROR(F21/W21,"")
A22: Aset tidak berwujud | D22: 1932.4396 | F22: ='Lap. PK - Kinerja Mei 2026'!E28 | I22: 2501.7194 | K22: =IFERROR(F22/I22-1,"") | M22: -76.868475 | O22: =F22-D22 | Q22: =IFERROR((O22/M22-1),"") | S22: 3459.5557 | U22: =IFERROR(F22/S22,"") | W22: 6637.5592 | Y22: =IFERROR(F22/W22,"")
A23: Aset lain-lain | D23: 1606.8143 | F23: ='Lap. PK - Kinerja Mei 2026'!E29 | I23: 2089.7957 | K23: =IFERROR(F23/I23-1,"") | M23: -4.0447445 | O23: =F23-D23 | Q23: 1 | S23: 3269.1219 | U23: =IFERROR(F23/S23,"") | W23: 3452.1927 | Y23: =IFERROR(F23/W23,"")
Q24: =IFERROR((O24/M24-1),"") | U24: =IFERROR(F24/S24,"") | Y24: =IFERROR(F24/W24,"")
Q25: =IFERROR((O25/M25-1),"") | U25: =IFERROR(F25/S25,"") | Y25: =IFERROR(F25/W25,"")
A26: LIABILITAS | D26: 2215684.3 | F26: =SUM(F28:F40) | I26: 2119296.8 | K26: =F26/I26-1 | M26: 37997.29 | O26: =SUM(O28:O41) | Q26: =IFERROR((O26/M26-1),"") | S26: =SUM(S28:S40) | U26: =IFERROR(F26/S26,"") | W26: =SUM(W28:W40) | Y26: =IFERROR(F26/W26,"")
Q27: =IFERROR((O27/M27-1),"") | U27: =IFERROR(F27/S27,"") | Y27: =IFERROR(F27/W27,"")
A28: Utang tawidh | D28: 140.22234 | F28: ='Lap. PK - Kinerja Mei 2026'!E35 | I28: 14437.973 | K28: 1 | M28: 123.47217 | O28: =F28-D28 | Q28: =IFERROR((O28/M28-1),"") | S28: 2104.7402 | U28: =IFERROR(F28/S28,"") | W28: 2145.9411 | Y28: =IFERROR(F28/W28,"")
A29: Utang penjaminan ulang | D29: 54666.206 | F29: ='Lap. PK - Kinerja Mei 2026'!E36 | I29: 33414.983 | K29: =IFERROR(F29/I29-1,"") | M29: 10324.837 | O29: =F29-D29 | Q29: =IFERROR((O29/M29-1),"") | S29: 45126.271 | U29: =IFERROR(F29/S29,"") | W29: 50512.811 | Y29: =IFERROR(F29/W29,"")
A30: Utang Komisi | D30: 7701.85 | F30: ='Lap. PK - Kinerja Mei 2026'!E37 | I30: 8363.863 | K30: =IFERROR(F30/I30-1,"") | M30: -37.374228 | O30: =F30-D30 | Q30: =IFERROR((O30/M30-1),"") | S30: 8593.9397 | U30: =IFERROR(F30/S30,"") | W30: 9136.4604 | Y30: =IFERROR(F30/W30,"")
A31: Pendapatan diterima dimuka | D31: 27854.927 | F31: ='Lap. PK - Kinerja Mei 2026'!E38 | I31: 31953.425 | K31: =IFERROR(F31/I31-1,"") | M31: 1849.1549 | O31: =F31-D31 | Q31: =IFERROR((O31/M31-1),"") | S31: 33478.039 | U31: =IFERROR(F31/S31,"") | W31: 31937.209 | Y31: =IFERROR(F31/W31,"")
A32: Utang zakat | D32: 4647.737 | F32: ='Lap. PK - Kinerja Mei 2026'!E39 | I32: 7421.6869 | K32: =IFERROR(F32/I32-1,"") | M32: 733.35217 | O32: =F32-D32 | Q32: =IFERROR((O32/M32-1),"") | S32: 8320.7672 | U32: =IFERROR(F32/S32,"") | W32: 7513.1761 | Y32: =IFERROR(F32/W32,"")
A33: Utang pajak | D33: 10838.232 | F33: ='Lap. PK - Kinerja Mei 2026'!E40 | I33: 10984.789 | K33: =IFERROR(F33/I33-1,"") | M33: 3055.5035 | O33: =F33-D33 | Q33: =IFERROR((O33/M33-1),"") | S33: 18912.062 | U33: =IFERROR(F33/S33,"") | W33: 18698.064 | Y33: =IFERROR(F33/W33,"")
A34: Beban akrual | D34: 41924.337 | F34: ='Lap. PK - Kinerja Mei 2026'!E41 | I34: 37009.013 | K34: =IFERROR(F34/I34-1,"") | M34: -3221.6797 | O34: =F34-D34 | Q34: =IFERROR((O34/M34-1),"") | S34: 54847.885 | U34: =IFERROR(F34/S34,"") | W34: 62693.418 | Y34: =IFERROR(F34/W34,"")
A35: Estimasi ta'widh retensi sendiri | D35: 463614.54 | F35: ='Lap. PK - Kinerja Mei 2026'!E42 | I35: 466670.28 | K35: =IFERROR(F35/I35-1,"") | M35: 20270.366 | O35: =F35-D35 | Q35: =IFERROR((O35/M35-1),"") | S35: 543869.2 | U35: =IFERROR(F35/S35,"") | W35: 657950.35 | Y35: =IFERROR(F35/W35,"")
A36: Estimasi ujrah yang belum merupakan pendapatan | D36: 1465413.5 | F36: ='Lap. PK - Kinerja Mei 2026'!E43 | I36: 1363677.9 | K36: =IFERROR(F36/I36-1,"") | M36: 5981.413 | O36: =F36-D36 | Q36: =IFERROR((O36/M36-1),"") | S36: 1453609.5 | U36: =IFERROR(F36/S36,"") | W36: 1502201.3 | Y36: =IFERROR(F36/W36,"")
A37: Pendapatan komisi yang ditangguhkan | D37: 128878.16 | F37: ='Lap. PK - Kinerja Mei 2026'!E44 | I37: 133230.32 | K37: =IFERROR(F37/I37-1,"") | M37: -1349.8138 | O37: =F37-D37 | Q37: =IFERROR((O37/M37-1),"") | S37: 141421.14 | U37: =IFERROR(F37/S37,"") | W37: 140161.51 | Y37: =IFERROR(F37/W37,"")
A38: Liabilitas imbalan kerja jangka panjang | D38: 246.29405 | F38: ='Lap. PK - Kinerja Mei 2026'!E45 | I38: 133.92676 | K38: =IFERROR(F38/I38-1,"") | M38: 112.36729 | O38: =F38-D38 | Q38: =IFERROR((O38/M38-1),"") | S38: 133.92676 | U38: =IFERROR(F38/S38,"") | W38: 133.92676 | Y38: =IFERROR(F38/W38,"")
A39: Utang Deviden | D39: 0 | F39: 0 | I39: 1156.9619 | K39: =IFERROR(F39/I39-1,"") | M39: 0 | O39: =F39-D39 | Q39: =IFERROR((O39/M39-1),"") | S39: 0 | U39: =IFERROR(F39/S39,"") | W39: 0 | Y39: =IFERROR(F39/W39,"")
A40: Utang lain-lain | D40: 9758.3049 | F40: ='Lap. PK - Kinerja Mei 2026'!E47 | I40: 10841.712 | K40: =IFERROR(F40/I40-1,"") | M40: 155.69163 | O40: =F40-D40 | Q40: =IFERROR((O40/M40-1),"") | S40: 10816.667 | U40: =IFERROR(F40/S40,"") | W40: 10977.528 | Y40: =IFERROR(F40/W40,"")
Q41: =IFERROR((O41/M41-1),"") | U41: =IFERROR(F41/S41,"") | Y41: =IFERROR(F41/W41,"")
...

Sheet CASH FLOW Mei 2026
A1: Laporan Arus Kas Konsolidasi Askrindo dan Entitas Anak
A2: (dalam Jutaan Rupiah)
A3: KETERANGAN | B3: REALISASI 2025 (Audited) | C3: RKAP 2026 | D3: REALISASI SD APRIL 2026 | E3: REALISASI SD MEI 2026 | F3: REALISASI SD MEI 2025 | G3: RASIO (%)
G4: PENCAPAIAN THDP RKAP 2026 | H4: PERB. DNG. TAHUN 2025
A5: 1 | B5: 2 | C5: 3 | D5: 4 | E5: 5 | F5: 6 | G5: 7 = 5 : 3 | H5: 8 = (5-6) : 6
A6: Arus Kas dari Aktivitas Operasi
A7: Penerimaan Premi dan Jasa Penjaminan | B7: 836483.69 | C7: 901614.23 | D7: 324675.25 | E7: 402640.18 | F7: 285291.82 | G7: =IFERROR(E7/C7*100," ") | H7: =IFERROR((E7/F7-1)*100," ")
A8: Penerimaan Recoveries | B8: 83357.094 | C8: 59838.445 | D8: 19650.767 | E8: 23867.007 | F8: 40708.37 | G8: =IFERROR(E8/C8*100," ") | H8: =IFERROR((E8/F8-1)*100," ")
A9: Pembayaran Klaim | B9: -561199.63 | C9: -532402.64 | D9: -189063.43 | E9: -238716.92 | F9: -142376.86 | G9: =IFERROR(E9/C9*100," ") | H9: =IFERROR((E9/F9-1)*100," ")
A10: Penerimaan Klaim Reasuransi | B10: 160839.24 | C10: 172490.02 | D10: 44472.372 | E10: 54607.115 | F10: 52615.836 | G10: =IFERROR(E10/C10*100," ") | H10: =IFERROR((E10/F10-1)*100," ")
A11: Pembayaran Premi Reasuransi | B11: -158270.99 | C11: -179704.19 | D11: -38286.262 | E11: -55677.546 | F11: -53321.308 | G11: =IFERROR(E11/C11*100," ") | H11: =IFERROR((E11/F11-1)*100," ")
A12: Penerimaan Lainnya | B12: 963.56548 | C12: 1142.0298 | D12: 1147.748 | E12: 1587.2975 | F12: 265.85234 | G12: =IFERROR(E12/C12*100," ") | H12: =IFERROR((E12/F12-1)*100," ")
A13: Pembayaran Beban Pemasaran, Umum dan Adm. | B13: -121342.22 | C13: -145659.4 | D13: -56146.792 | E13: -67425.302 | F13: -54833.302 | G13: =IFERROR(E13/C13*100," ") | H13: =IFERROR((E13/F13-1)*100," ")
A14: Pembayaran Komisi | B14: -26407.318 | C14: -28444.964 | D14: -11179.315 | E14: -12851.728 | F14: -8005.3903 | G14: =IFERROR(E14/C14*100," ") | H14: =IFERROR((E14/F14-1)*100," ")
A15: Pembayaran Lainnya | B15: -64212.981 | C15: -60241.707 | D15: -24859.737 | E15: -30539.192 | F15: -21056.066 | G15: =IFERROR(E15/C15*100," ") | H15: =IFERROR((E15/F15-1)*100," ")
A16: Kas Bersih dihasilkan (dikeluarkan) dari aktivitas operasi | B16: 150210.45 | C16: 188631.81 | D16: 70410.606 | E16: 77490.908 | F16: 99288.948 | G16: =IFERROR(E16/C16*100," ") | H16: =IFERROR((E16/F16-1)*100," ")
G17: =IFERROR(E17/C17*100," ") | H17: =IFERROR((E17/F17-1)*100," ")
A18: Arus Kas dari Aktivitas Investasi | G18: =IFERROR(E18/C18*100," ") | H18: =IFERROR((E18/F18-1)*100," ")
A19: Penerimaan hasil investasi | B19: 151151.23 | C19: 157861.78 | D19: 43082.948 | E19: 55193.493 | F19: 58496.037 | G19: =IFERROR(E19/C19*100," ") | H19: =IFERROR((E19/F19-1)*100," ")
A20: Pencairan (Penempatan) Deposito | B20: -111800 | C20: -17000 | D20: 131300 | E20: 129050 | F20: -45250 | G20: =IFERROR(E20/C20*100," ") | H20: =IFERROR((E20/F20-1)*100," ")
A21: Pencairan (Penempatan) Surat Berharga | B21: -193855.21 | C21: -284426.46 | D21: -236813.1 | E21: -254940.4 | F21: -99051.486 | G21: =IFERROR(E21/C21*100," ") | H21: =IFERROR((E21/F21-1)*100," ")
A22: Hasil Penjualan Aset Tetap | C22: 0 | G22: =IFERROR(E22/C22*100," ") | H22: =IFERROR((E22/F22-1)*100," ")
A23: Perolehan Aset Tetap | B23: -2498.6573 | C23: -9541.148 | D23: -82.474778 | E23: -104.77478 | F23: -44.708493 | G23: =IFERROR(E23/C23*100," ") | H23: =IFERROR((E23/F23-1)*100," ")
A24: Penerimaan (Penempatan) Penyertaan Langsung | C24: 0 | G24: =IFERROR(E24/C24*100," ") | H24: =IFERROR((E24/F24-1)*100," ")
A25: Kas Bersih dihasilkan (dikeluarkan) dari aktivitas investasi | B25: -157002.64 | C25: -153105.83 | D25: -62512.626 | E25: -70801.683 | F25: -85850.157 | G25: =IFERROR(E25/C25*100," ") | H25: =IFERROR((E25/F25-1)*100," ")
G26: =IFERROR(E26/C26*100," ") | H26: =IFERROR((E26/F26-1)*100," ")
A27: Arus Kas dari Aktivitas Pendanaan | G27: =IFERROR(E27/C27*100," ") | H27: =IFERROR((E27/F27-1)*100," ")
A28: Penerimaan (Pembayaran) deviden | B28: -23207.172 | C28: -14110.422 | D28: 0 | E28: 0 | F28: 0 | G28: =IFERROR(E28/C28*100," ") | H28: =IFERROR((E28/F28-1)*100," ")
A29: Penerimaan atas Tambahan Modal disetor | B29: 0 | C29: 0 | D29: 0 | E29: 0 | F29: 0 | G29: =IFERROR(E29/C29*100," ") | H29: =IFERROR((E29/F29-1)*100," ")
A30: Penyaluran Dana Program Kemitraan dan Bina Lingkungan | C30: 0 | G30: =IFERROR(E30/C30*100," ") | H30: =IFERROR((E30/F30-1)*100," ")
A31: Kas Bersih dihasilkan (dikeluarkan) dari aktivitas pendanaan | B31: -23207.172 | C31: -14110.422 | D31: 0 | E31: 0 | F31: 0 | G31: =IFERROR(E31/C31*100," ") | H31: =IFERROR((E31/F31-1)*100," ")
C32: 0 | G32: =IFERROR(E32/C32*100," ") | H32: =IFERROR((E32/F32-1)*100," ")
A33: KENAIKAN/PENURUNAN SALDO KAS | B33: -29999.37 | C33: 21415.565 | D33: 7897.9801 | E33: 6689.2251 | F33: 13438.79 | G33: =IFERROR(E33/C33*100," ") | H33: =IFERROR((E33/F33-1)*100," ")
A34: Kas dan Setara Kas pada Awal Tahun | B34: 103869.27 | C34: 99508.07 | D34: 73869.903 | E34: 73869.903 | F34: 103869.27 | G34: =IFERROR(E34/C34*100," ") | H34: =IFERROR((E34/F34-1)*100," ")
G35: =IFERROR(E35/C35*100," ") | H35: =IFERROR((E35/F35-1)*100," ")
A36: Kas dan Setara Kas pada Akhir Tahun | B36: 73869.903 | C36: 120923.64 | D36: 81962.748 | E36: 80559.128 | F36: 117308.06 | G36: =IFERROR(E36/C36*100," ") | H36: =IFERROR((E36/F36-1)*100," ")

Sheet Hasil Underwriting
L1: Lampiran 1
A3: REALISASI HASIL UNDERWRITING
A4: PERIODE 1 JANUARI S/D 31 Mei 2026
A5: PT Jaminan Pembiayaan Askrindo Syariah
A6: (dalam jutaan rupiah)
A7: U R A I A N | B7: RKAP 2026 | C7: REALISASI s.d. Mei 2026 | D7: C L A S S O F B U S I N E S S | L7: % PENCAPAIAN THDP RKAP 2026
D8: Mikro | E8: Retail & Korporasi | F8: PEN | G8: KUR | H8: Konsumtif | I8: KBG | J8: Surety | K8: KPP
A10: 1 | B10: 2 | C10: 3 | D10: 4 | E10: 5 | F10: 6 | G10: 7 | H10: 8 | I10: 9 | J10: 10 | K10: 11 | L10: 12 = 3 : 2
A12: Pendapatan Premi
A13: Imbal Jasa Kafalah | B13: 9.037e+11 | C13: =SUM(D13:K13) | D13: ='Input HUW'!F4 | E13: ='Input HUW'!G4 | F13: ='Input HUW'!I4 | G13: ='Input HUW'!H4 | H13: ='Input HUW'!J4 | I13: ='Input HUW'!K4 | J13: ='Input HUW'!L4 | K13: ='Input HUW'!M4 | L13: =C13/B13
A14: Beban Penjaminan Ulang | B14: -2.3591461e+11 | C14: =SUM(D14:K14) | D14: ='Input HUW'!F6 | E14: ='Input HUW'!G6 | F14: ='Input HUW'!I6 | G14: ='Input HUW'!H6 | H14: ='Input HUW'!J6 | I14: ='Input HUW'!K6 | J14: ='Input HUW'!L6 | K14: ='Input HUW'!M6 | L14: =C14/B14
A15: Komisi penjaminan ulang | B15: 4.9076638e+10 | C15: =SUM(D15:K15) | D15: ='Input HUW'!F7+'Input HUW'!F8 | E15: ='Input HUW'!G7+'Input HUW'!G8 | F15: ='Input HUW'!I7+'Input HUW'!I8 | G15: ='Input HUW'!H7+'Input HUW'!H8 | H15: ='Input HUW'!J7+'Input HUW'!J8 | I15: ='Input HUW'!K7+'Input HUW'!K8 | J15: ='Input HUW'!L7+'Input HUW'!L8 | K15: ='Input HUW'!M7+'Input HUW'!M8 | L15: =C15/B15
A16: Penurunan (Kenaikan) Cad. Premi | B16: -9.1333788e+10 | C16: =SUM(D16:K16) | D16: ='Input HUW'!F9 | E16: ='Input HUW'!G9 | F16: ='Input HUW'!I9 | G16: ='Input HUW'!H9 | H16: ='Input HUW'!J9 | I16: ='Input HUW'!K9 | J16: ='Input HUW'!L9 | K16: ='Input HUW'!M9 | L16: =C16/B16
A17: Pendapatan Kafalah Lain | B17: 1.3610185e+08 | C17: =SUM(D17:K17) | D17: ='Input HUW'!F10 | E17: ='Input HUW'!G10 | F17: ='Input HUW'!I10 | G17: ='Input HUW'!H10 | H17: ='Input HUW'!J10 | I17: ='Input HUW'!K10 | J17: ='Input HUW'!L10 | K17: ='Input HUW'!M10 | L17: =C17/B17
A19: Jumlah Pendapatan Premi | B19: =SUM(B13:B18) | C19: =SUM(C13:C18) | D19: =SUM(D13:D18) | E19: =SUM(E13:E18) | F19: =SUM(F13:F18) | G19: =SUM(G13:G18) | H19: =SUM(H13:H18) | I19: =SUM(I13:I18) | ... K19: =SUM(K13:K18) | L19: =C19/B19
A21: Beban Underwriting
A22: Ta'widh Gross | B22: 5.3247327e+11 | C22: =SUM(D22:K22) | D22: ='Input HUW'!F13 | E22: ='Input HUW'!G13 | F22: ='Input HUW'!I13 | G22: ='Input HUW'!H13 | H22: ='Input HUW'!J13 | I22: ='Input HUW'!K13 | J22: ='Input HUW'!L13 | K22: ='Input HUW'!M13 | L22: =C22/B22
A23: Ta'widh Reas | B23: -1.7317154e+11 | C23: =SUM(D23:K23) | D23: ='Input HUW'!F14 | E23: ='Input HUW'!G14 | F23: ='Input HUW'!I14 | G23: ='Input HUW'!H14 | H23: ='Input HUW'!J14 | I23: ='Input HUW'!K14 | J23: ='Input HUW'!L14 | K23: ='Input HUW'!M14 | L23: =C23/B23
A24: Beban Komisi - bersih | B24: 2.578105e+10 | C24: =SUM(D24:K24) | D24: ='Input HUW'!F15+'Input HUW'!F16 | E24: ='Input HUW'!G15+'Input HUW'!G16 | F24: ='Input HUW'!I15+'Input HUW'!I16 | G24: ='Input HUW'!H15+'Input HUW'!H16 | H24: ='Input HUW'!J15+'Input HUW'!J16 | I24: ='Input HUW'!K15+'Input HUW'!K16 | J24: ='Input HUW'!L15+'Input HUW'!L16 | K24: ='Input HUW'!M15+'Input HUW'!M16 | L24: =C24/B24
A25: Pendapatan Recoveries - bersih | B25: -5.9838445e+10 | C25: =SUM(D25:K25) | D25: ='Input HUW'!F17 | E25: ='Input HUW'!G17 | F25: ='Input HUW'!I17 | G25: ='Input HUW'!H17 | H25: ='Input HUW'!J17 | I25: ='Input HUW'!K17 | J25: ='Input HUW'!L17 | K25: ='Input HUW'!M17 | L25: =C25/B25
A26: Kenaikan (Penurunan) Estimasi Ta'widh | B26: 7.0070686e+10 | C26: =SUM(D26:K26) | D26: ='Input HUW'!F18 | E26: ='Input HUW'!G18 | F26: ='Input HUW'!I18 | G26: ='Input HUW'!H18 | H26: ='Input HUW'!J18 | I26: ='Input HUW'!K18 | J26: ='Input HUW'!L18 | K26: ='Input HUW'!M18 | L26: =C26/B26
A27: Beban Underwriting Lain | B27: 3.2992045e+09 | C27: =SUM(D27:K27) | D27: ='Input HUW'!F19 | E27: ='Input HUW'!G19 | F27: ='Input HUW'!I19 | G27: ='Input HUW'!H19 | H27: ='Input HUW'!J19 | I27: ='Input HUW'!K19 | J27: ='Input HUW'!L19 | K27: ='Input HUW'!M19 | L27: =C27/B27
A29: Jumlah Beban Underwriting | B29: =SUM(B22:B27) | C29: =SUM(C22:C27) | D29: =SUM(D22:D27) | E29: =SUM(E22:E27) | F29: =SUM(F22:F27) | G29: =SUM(G22:G27) | H29: =SUM(H22:H27) | I29: =SUM(I22:I27) | ... K29: =SUM(K22:K27) | L29: =C29/B29
A31: Hasil Underwriting | B31: =B19-B29 | C31: =C19-C29 | D31: =D19-D29 | E31: =E19-E29 | F31: =F19-F29 | G31: =G19-G29 | H31: =H19-H29 | I31: =I19-I29 | ... K31: =K19-K29 | L31: =C31/B31

Sheet Input HUW
B2: INDIKATOR | C2: REALISASI JANUARI S/D FEBRUARI 2023 | D2: Realisasi sd Mei 2026 | P2: INDIKATOR
C3: TOTAL PRODUKTIF NON PROGRAM | D3: MIKRO PNM | E3: MIKRO NON PNM | F3: Mikro | G3: Retail & Korporasi | H3: KUR | I3: PEN | J3: Konsumtif | K3: KBG | L3: Surety | M3: KPP | N3: Total | Q3: Mikro | R3: Retail & Korporasi | S3: KUR | T3: PEN | U3: Konsumtif | V3: KBG | W3: Surety | X3: KPP | Y3: Total
B4: Imbal Jasa Kafalah Bruto | F4: 1.6576775e+11 | G4: 5.6527364e+09 | H4: 1.6506855e+11 | I4: 0 | J4: 1.9287765e+10 | K4: 3.2182935e+09 | L4: 35951042 | M4: 46044228200 | N4: =SUM(F4:M4) | P4: Imbal Jasa Kafalah Bruto | Q4: 1.4408064e+11 | R4: 4.8899243e+09 | S4: 1.2447017e+11 | T4: 0 | U4: 1.5789553e+10 | V4: 2.6711066e+09 | W4: 26577993 | X4: 36194650200 | Y4: 3.2812262e+11
N5: 0 | Q5: 0 | R5: 0 | S5: 0 | T5: 0 | U5: 0 | V5: 0 | W5: 0 | X5: 0 | Y5: 0
B6: Beban Penjaminan Ulang | F6: -4.1358321e+10 | G6: -2.2765399e+09 | H6: -4.0224766e+10 | I6: 0 | J6: -2.10899e+09 | K6: -1.3136673e+09 | L6: -9012760.6 | M6: -11511057050 | N6: =SUM(F6:M6) | P6: Beban Penjaminan Ulang | Q6: -3.5928577e+10 | R6: -2.0858369e+09 | S6: -2.9984358e+10 | T6: 0 | U6: -1.7473137e+09 | V6: -1.0957695e+09 | W6: -6669498.3 | X6: -9048662550 | Y6: -7.9897187e+10
B7: Komisi penjaminan ulang | F7: 1.0811279e+10 | G7: 5.0643409e+08 | H7: 9.9880431e+09 | I7: 0 | J7: 5.4517736e+08 | K7: 3.2328692e+08 | L7: 2393429 | M7: 2.8809769e+09 | N7: =SUM(F7:M7) | P7: Komisi penjaminan ulang | Q7: 9.4535139e+09 | R7: 4.5801231e+08 | S7: 7.3696048e+09 | T7: 0 | U7: 4.5486371e+08 | V7: 2.6880002e+08 | W7: 1802801.5 | X7: 2.2653783e+09 | Y7: 2.0271976e+10
B8: Komisi penjaminan ulang Tangguhan | F8: -5.3642607e+08 | G8: 8.5097398e+08 | H8: 4.5989555e+09 | I8: 0 | J8: 1.2940655e+09 | K8: -1.4972845e+08 | L8: 10342476 | M8: -2.6413733e+09 | N8: =SUM(F8:M8) | P8: Komisi penjaminan ulang Tangguhan | Q8: -1.492387e+09 | R8: 6.089964e+08 | S8: 4.1223826e+09 | T8: 0 | U8: 1.0005849e+09 | V8: -1.3945534e+08 | W8: 8196229.2 | X8: -2.1032777e+09 | Y8: 2.0050402e+09
B9: Penurunan (Kenaikan) IJK YBMP | F9: -2.9282313e+10 | G9: 1.5603493e+09 | H9: -5.3994189e+09 | I9: 0 | J9: -7.6386954e+08 | K9: -6.0221665e+08 | L9: 1.0740688e+08 | M9: -3.1725179e+10 | N9: =SUM(F9:M9) | P9: Penurunan (Kenaikan) IJK YBMP | Q9: -3.5056315e+10 | R9: 9.8684528e+08 | S9: -1.0023153e+09 | T9: 0 | U9: -1.5354459e+09 | V9: -5.9889895e+08 | W9: 85310561 | X9: -2.5258864e+10 | Y9: -6.2379684e+10
B10: Pendapatan Kafalah Lain | F10: 16219121 | G10: 553077.5 | H10: 16150709 | I10: 0 | J10: 1887161.9 | K10: 314885.68 | L10: 3517.5376 | M10: 4505079.5 | N10: =SUM(F10:M10) | P10: Pendapatan Kafalah Lain | Q10: 13809251 | R10: 468669.42 | S10: 11929706 | T10: 0 | U10: 1513332.3 | V10: 256009.28 | W10: 2547.3386 | X10: 3469036.5 | Y10: 31448552
B11: Jumlah Pendapatan Kafalah | F11: 1.0541819e+11 | G11: 6.294507e+09 | H11: 1.3404751e+11 | I11: 0 | J11: 1.8256035e+10 | K11: 1.4762829e+09 | L11: 1.4708459e+08 | M11: 3.0521012e+09 | N11: =SUM(F11:M11) | P11: Jumlah Pendapatan Kafalah | Q11: 5.7824621e+10 | R11: 3.5291298e+09 | S11: 7.7808854e+10 | T11: 0 | U11: 9.8654068e+09 | V11: 7.6601806e+08 | W11: 85792820 | X11: 9.5042416e+08 | Y11: 1.5083025e+11
N12: =SUM(F12:M12) | Y12: 0
B13: Ta'widh Bruto | F13: 1.2690423e+11 | G13: 1.5761998e+08 | H13: 9.9453924e+10 | I13: 0 | J13: 1.2032623e+10 | K13: 0 | L13: 0 | M13: 0 | N13: =SUM(F13:M13) | P13: Ta'widh Bruto | Q13: 1.0690095e+11 | R13: 36160438 | S13: 7.4115094e+10 | T13: 0 | U13: 7.9376334e+09 | V13: 0 | W13: 0 | X13: 0 | Y13: 1.8898984e+11
B14: Ta'widh Reas | F14: -3.3905391e+10 | G14: -59674768 | H14: -3.1887827e+10 | I14: 0 | J14: -1.0746723e+10 | K14: 0 | L14: 0 | M14: 0 | N14: =SUM(F14:M14) | P14: Ta'widh Reas | Q14: -2.8527555e+10 | R14: -29309883 | S14: -2.3778423e+10 | T14: 0 | U14: -7.9209565e+09 | V14: 0 | W14: 0 | X14: 0 | Y14: -6.0256244e+10
B15: Akuisisi | F15: 1.2566109e+10 | G15: 0 | H15: 0 | I15: 0 | J15: 15000 | K15: 2174094 | L15: 0 | M15: 0 | N15: =SUM(F15:M15) | P15: Akuisisi | Q15: 1.0930523e+10 | R15: 0 | S15: 0 | T15: 0 | U15: 15000 | V15: 2174094 | W15: 0 | X15: 0 | Y15: 1.0932712e+10
B16: Akuisisi Tangguhan | F16: -2.7315404e+09 | G16: 72275894 | H16: 0 | I16: 0 | J16: 1.2726199e+09 | K16: 5688569.4 | L16: 14385646 | M16: 0 | N16: =SUM(F16:M16) | P16: Akuisisi Tangguhan | Q16: -3.3748191e+09 | R16: 1.1539582e+08 | S16: -57575104 | T16: 0 | U16: 1.0180929e+09 | V16: 4116036.7 | W16: 11508517 | X16: 0 | Y16: -2.2832809e+09
B17: Recoveries | F17: -5.9371469e+09 | G17: -2.2887375e+08 | H17: -1.6706995e+10 | I17: -88327116 | J17: -9.0566424e+08 | K17: 0 | L17: 0 | M17: 0 | N17: =SUM(F17:M17) | P17: Recoveries | Q17: -4.8027085e+09 | R17: -2.0946552e+08 | S17: -1.3721323e+10 | T17: -71862239 | U17: -8.454077e+08 | V17: 0 | W17: 0 | X17: 0 | Y17: -1.9650767e+10
B18: Kenaikan (Penurunan) ETRS | F18: 4.4816992e+08 | G18: -4.5997038e+08 | H18: 2.0940458e+10 | I18: 0 | J18: -4.0745792e+09 | K18: 0 | L18: -1.1279677e+08 | M18: 0 | N18: =SUM(F18:M18) | P18: Kenaikan (Penurunan) ETRS | Q18: 3.3002966e+08 | R18: -6.4801849e+08 | S18: 2.6430628e+10 | T18: 0 | U18: -6.0313849e+09 | V18: 0 | W18: -1.1279677e+08 | X18: 0 | Y18: 1.9968458e+10
B19: Beban Kafalah Lain | F19: 4.4427874e+08 | G19: 551811.45 | H19: 3.4817803e+08 | I19: 0 | J19: 42124984 | K19: 0 | L19: 0 | M19: 0 | N19: =SUM(F19:M19) | P19: Beban Kafalah Lain | Q19: 3.9597357e+08 | R19: 133942.48 | S19: 2.7453094e+08 | T19: 0 | U19: 29401918 | V19: 0 | W19: 0 | X19: 0 | Y19: 7.0004037e+08
B20: Jumlah Beban Kafalah | F20: 9.7788706e+10 | G20: -5.1807122e+08 | H20: 7.2147737e+10 | I20: -88327116 | J20: -2.3795833e+09 | K20: 7862663.4 | L20: -98411122 | M20: 0 | N20: =SUM(F20:M20) | P20: Jumlah Beban Kafalah | Q20: 6.8819743e+10 | R20: -1.5728292e+09 | S20: 4.9180486e+10 | T20: -60988020 | U20: -5.4169623e+09 | V20: 4717598 | W20: -1.0416538e+08 | X20: 0 | Y20: 1.1085e+11
N21: =SUM(F21:M21) | Y21: =SUM(Q21:X21)
F22: 7.6294838e+09 | G22: 6.8125782e+09 | H22: 6.1899775e+10 | I22: 88327116 | J22: 2.0635618e+10 | K22: 1.4684203e+09 | L22: 2.4549571e+08 | M22: 3.0521012e+09 | N22: =SUM(F22:M22) | Q22: -1.0995122e+10 | R22: 5.101959e+09 | S22: 2.8628369e+10 | T22: 60988020 | U22: 1.5282369e+10 | V22: 7.6130047e+08 | W22: 1.899582e+08 | X22: 9.5042416e+08 | Y22: =SUM(Q22:X22)
B24: Hijau = sudah diupdate

Sheet Investasi Mei 2026
A2: LAPORAN KINERJA INVESTASI
A3: PER 31 Mei 2026
A4: PT. JAMINAN PEMBIAYAAN ASKRINDO SYARIAH
A6: Uraian | D6: RKAP 2026 | E6: Realisasi 2026 | H6: Realisasi 2025 | K6: Rasio (%)
E7: s.d. April 2026 | F7: Mei 2026 | G7: s.d. Mei 2026 | H7: s.d. April 2025 | I7: Mei 2025 | J7: s.d. Mei 2025 | K7: Pencapaian Terhadap RKAP 2026 | L7: Pertumbuhan Terhadap Bulan Yang Sama Tahun Lalu
A8: 1 | D8: 2 | E8: 3 | F8: 4=5-3 | G8: 5 | H8: 6 | I8: 7 = 8 -6 | J8: 8 | K8: 9 = 5 : 2 | L8: 10 = (5-8) : 8
A9: A. POSISI INVESTASI
B10: 1. | C10: Deposito | D10: 454400 | E10: 427450 | F10: 5100 | G10: 432550 | H10: 402200 | I10: 7850 | J10: 410050 | K10: 0.87400794 | L10: 0.054871357
C11: - Deposito yang dibatasi penggunaanya | D11: 100000 | E11: 50000 | F11: 0 | G11: 50000 | H11: 80000 | I11: 0 | J11: 80000 | K11: 0.5 | L11: -0.375
B12: 2. | C12: DOC | D12: 0 | E12: 4850 | F12: -2850 | G12: 2000 | H12: 90000 | I12: -33000 | J12: 57000 | K12: 0 | L12: -
B13: 3. | C13: Surat Berharga | D13: =SUM(D14:D16) | E13: 2017533.6 | F13: 13240.932 | G13: 2030774.6 | H13: 1669821 | I13: 47592.608 | J13: 1717413.6 | K13: 0.93305431 | L13: 0.18246099
C14: - Reksadana | D14: 142246.67 | E14: 100625.15 | F14: 10186.56 | G14: 110811.71 | H14: 90981.26 | I14: -10232.662 | J14: 80748.598 | K14: 0.77901093 | L14: 0.37230505
C15: -Saham | D15: 0 | E15: 0 | F15: 0 | G15: 0 | H15: 0 | I15: 0 | J15: 0 | K15: - | L15: -
C16: -Obligasi | D16: =D17+D18 | E16: 1916908.5 | F16: 3054.3717 | G16: 1919962.9 | H16: 1578839.7 | I16: 57825.27 | J16: 1636665 | K16: 0.94382601 | L16: 0.1730946
C17: Obligasi Pemerintah | D17: 1756273.9 | E17: 1893583.5 | F17: 3054.3717 | G17: 1896637.9 | H17: 1565839.7 | I17: 47825.27 | J17: 1613665 | K17: 1.0799215 | L17: 0.17536036
C18: Obligasi Korporasi | D18: 277960 | E18: 23325 | F18: 0 | G18: 23325 | H18: 13000 | I18: 10000 | J18: 23000 | K18: 0.083914952 | L18: 0.014130435
A19: TOTAL POSISI INVESTASI | D19: =D10+D11+D12+D13 | E19: 2499833.6 | F19: 15490.932 | G19: 2515324.6 | H19: 2242021 | I19: 22442.608 | J19: 2264463.6 | K19: 0.92106722 | L19: 0.11078164
A20: B. HASIL INVESTASI
B21: 1. | C21: Deposito | D21: 25260.5 | E21: 9178.2382 | F21: 1683.0568 | G21: 10861.295 | H21: 8956.7512 | I21: 2091.8582 | J21: 11048.609 | K21: 0.42997149 | L21: -0.016953673
B22: 2. | C22: DOC | D22: 0 | E22: 228.08757 | F22: 1.8083327 | G22: 229.8959 | H22: 50.495709 | I22: 69.377626 | J22: 119.87333 | K22: - | L22: -
B23: 3. | C23: Surat Berharga | D23: =SUM(D24:D26) | E23: 40756.013 | F23: 10709.131 | G23: 51465.144 | H23: 38095.145 | I23: 9938.749 | J23: 48033.893 | K23: 0.37803341 | L23: 0.071433946
C24: - Reksadana | D24: 7150.1572 | E24: 1103.4816 | F24: 225.05384 | G24: 1328.5354 | H24: 1762.9859 | I24: 679.07809 | J24: 2442.064 | K24: 0.18580507 | L24: -0.45597845
C25: -Saham | D25: 0 | E25: 0 | F25: 0 | G25: 0 | H25: 0 | I25: 0 | J25: 0 | K25: - | L25: -
C26: -Obligasi | D26: =D27+D28 | E26: 39652.531 | F26: 10484.077 | G26: 50136.609 | H26: 36332.159 | I26: 9259.6709 | J26: 45591.829 | K26: 0.38868907 | L26: 0.09968407
C27: Obligasi Pemerintah | D27: 118773.9 | E27: 38945.711 | F27: 10354.717 | G27: 49300.428 | H27: 36027.155 | I27: 9179.7264 | J27: 45206.882 | K27: 0.41507798 | L27: 0.090551401
C28: Obligasi Korporasi | D28: 10215.09 | E28: 706.82009 | F28: 129.36042 | G28: 836.18051 | H28: 305.00342 | I28: 79.944444 | J28: 384.94787 | K28: 0.081857381 | L28: 1.1721916
A29: TOTAL HASIL INVESTASI | D29: =D21+D22+D23 | E29: 50162.338 | F29: 12393.996 | G29: 62556.335 | H29: 47102.391 | I29: 12099.985 | J29: 59202.376 | K29: 0.38758658 | L29: 0.056652432
C31: Catatan :
B32: 1 | C32: Terdapat deposito yang dibatasi penggunaannya (restricted cash) sebesar Rp. 50 Miliar
B33: 2 | C33: Nilai tersebut (Rp. 50 Miliar) didalam neraca disajikan terpisah dengan investasi, namun pada kertas kerja ini
C34: kami tetap mengkategorikan sebagai instrumen deposito, mengingat dana tersebut secara prinsip merupakan
C35: deposito JPAS
B36: 3 | C36: Hasil Investasi disajikan secara Gross

Sheet List Deposito per Bank 
B1: RINGKASAN DATA DEPOSITO PER BANK (Mei 2026)
B2: NO | C2: NAMA BANK | D2: NOMINAL (Rp) | E2: JUMLAH BILYET
B3: 1 | C3: BANK SYARIAH INDONESIA | D3: 325850000000 | E3: 680
B4: 2 | C4: BANK SYARIAH NASIONAL | D4: 89500000000 | E4: 28
B5: 3 | C5: BANK PANIN DUBAI SYARIAH | D5: 17000000000 | E5: 7
B6: 4 | C6: BANK ACEH SYARIAH | D6: 12000000000 | E6: 6
B7: 5 | C7: BANK BPD JATENG SYARIAH | D7: 7000000000 | E7: 14
B8: 6 | C8: BANK BPR SYARIAH DINAR ASHRI | D8: 6000000000 | E8: 5
B9: 7 | C9: BANK BPD JATIM SYARIAH | D9: 5000000000 | E9: 2
B10: 8 | C10: BANK JABAR BANTEN SYARIAH | D10: 4000000000 | E10: 2
B11: 9 | C11: BANK SULSELBAR SYARIAH | D11: 3950000000 | E11: 5
B12: 10 | C12: BANK RIAU KEPRI SYARIAH | D12: 3650000000 | E12: 13
B13: 11 | C13: BANK SYARIAH BUKOPIN | D13: 3500000000 | E13: 6
B14: 12 | C14: BANK BTPN SYARIAH | D14: 2500000000 | E14: 1
... B19: 17 | C19: BANK BPD KALTIM KALTARA | D19: 100000000 | E19: 1
B20: TOTAL | D20: 484550000000 | E20: 775

Sheet Lap. LR-Kinerja Mei 2026
C1: PT JAMINAN PEMBIAYAAN ASKRINDO SYARIAH
C2: LAPORAN LABA RUGI KOMPREHENSIF
C3: Periode 1 Januari s.d 31 Mei 2026
G4: (Jutaan Rp)
C5: URAIAN | D5: Realisasi 1 Jan s.d 31 Des 2025 (Audited) | E5: Anggaran 1 Jan s.d 31 Des 2026 | F5: Realisasi s.d 31 Mei 2026 | G5: Rasio (%)
C7: 1 | D7: 2 | E7: 3 | F7: 4 | G7: 5 (4:3) | H7: 6 (4:2)
C8: PENDAPATAN KAFALAH
C9: Imbal jasa kafalah bruto | D9: 834065.23 | E9: 903700 | F9: 405075.27 | G9: =IFERROR((F9/E9)*100,"") | H9: =IFERROR((F9/D9)*100,"") | J9: Revenue
C10: Imbal jasa penjaminan ulang | D10: 0 | G10: =IFERROR((F10/E10)*100,"") | H10: =IFERROR((F10/D10)*100,"")
C11: Beban penjaminan ulang | D11: -220622.29 | E11: -235914.61 | F11: -98802.353 | G11: =IFERROR((F11/E11)*100,"") | H11: =IFERROR((F11/D11)*100,"") | J11: OpEx mirip dengan contra revenue
C12: Komisi penjaminan ulang | D12: 64844.141 | E12: 46976.345 | F12: 25057.591 | G12: =IFERROR((F12/E12)*100,"") | H12: =IFERROR((F12/D12)*100,"")
C13: Komisi penjaminan ulang tangguhan | D13: 6497.6313 | E13: 2100.2925 | F13: 3426.8096 | G13: =IFERROR((F13/E13)*100,"") | H13: =IFERROR((F13/D13)*100,"")
C14: Penurunan (Kenaikan) IJK YBMP | D14: -74516.128 | E14: -91333.788 | F14: -66105.241 | G14: =IFERROR((F14/E14)*100,"") | H14: =IFERROR((F14/D14)*100,"") | J14: Cadangan premi (unearned revenue)
C15: Penerimaan kafalah lain | D15: 127.52209 | E15: 136.10185 | F15: 39.633552 | G15: =IFERROR((F15/E15)*100,"") | H15: =IFERROR((F15/D15)*100,"")
C16: Jumlah Pendapatan Kafalah | D16: 610396.1 | E16: 625664.34 | F16: 268691.71 | G16: =IFERROR((F16/E16)*100,"") | H16: =IFERROR((F16/D16)*100,"") | J16: Net Revenue
G17: =IFERROR((F17/E17)*100,"") | H17: =IFERROR((F17/D17)*100,"")
C18: BEBAN KAFALAH | G18: =IFERROR((F18/E18)*100,"") | H18: =IFERROR((F18/D18)*100,"")
C19: Tawidh | D19: 561288.82 | E19: 532473.27 | F19: 238548.39 | G19: =IFERROR((F19/E19)*100,"") | H19: =IFERROR((F19/D19)*100,"") | J19: COGS
C20: Tawidh Reas | D20: -178340.37 | E20: -173171.54 | F20: -76599.616 | G20: =IFERROR((F20/E20)*100,"") | H20: =IFERROR((F20/D20)*100,"") | J20: (-) Purchase Returns & Allowances
C21: Beban akuisisi | D21: 25840.813 | E21: 29375 | F21: 12568.298 | G21: =IFERROR((F21/E21)*100,"") | H21: =IFERROR((F21/D21)*100,"") | J21: ?
C22: Beban akuisisi tangguhan | D22: -1348.2332 | E22: -3593.95 | F22: -1366.5704 | G22: =IFERROR((F22/E22)*100,"") | H22: =IFERROR((F22/D22)*100,"") | J22: ?
C23: Subrogasi | D23: -83357.094 | E23: -59838.445 | F23: -23867.007 | G23: =IFERROR((F23/E23)*100,"") | H23: =IFERROR((F23/D23)*100,"") | J23: recoveries
C24: Kenaikan (Penurunan) ETRS | D24: 76623.549 | E24: 70070.686 | F24: 16741.281 | G24: =IFERROR((F24/E24)*100,"") | H24: =IFERROR((F24/D24)*100,"") | J24: Bad Debt Expense
C25: Beban kafalah lain | D25: 2980.3344 | E25: 3299.2045 | F25: 835.13356 | G25: =IFERROR((F25/E25)*100,"") | H25: =IFERROR((F25/D25)*100,"")
C26: Jumlah Beban Kafalah | D26: 403687.82 | E26: 398614.22 | F26: 166859.91 | G26: =IFERROR((F26/E26)*100,"") | H26: =IFERROR((F26/D26)*100,"")
C27: Pendapatan Kafalah Bersih | D27: 206708.28 | E27: 227050.12 | F27: 101831.8 | G27: =IFERROR((F27/E27)*100,"") | H27: =IFERROR((F27/D27)*100,"") | J27: Gross Profit
G28: =IFERROR((F28/E28)*100,"") | H28: =IFERROR((F28/D28)*100,"")
C29: NISBAH (BAGI HASIL) INVESTASI | D29: 153658.39 | E29: 161399.64 | F29: 62556.335 | G29: =IFERROR((F29/E29)*100,"") | H29: =IFERROR((F29/D29)*100,"")
G30: =IFERROR((F30/E30)*100,"") | H30: =IFERROR((F30/D30)*100,"")
C31: BEBAN USAHA | G31: =IFERROR((F31/E31)*100,"") | H31: =IFERROR((F31/D31)*100,"") | J31: OpEX (SG&A)
C32: Beban Pemasaran | D32: 13136.563 | E32: 14704.226 | F32: 5562.0003 | G32: =IFERROR((F32/E32)*100,"") | H32: =IFERROR((F32/D32)*100,"")
C33: Beban Umum | D33: 99161.776 | E33: 120237.58 | F33: 44696.839 | G33: =IFERROR((F33/E33)*100,"") | H33: =IFERROR((F33/D33)*100,"")
C34: Beban Administrasi | D34: 20726.068 | E34: 24287.176 | F34: 7451.6472 | G34: =IFERROR((F34/E34)*100,"") | H34: =IFERROR((F34/D34)*100,"")
C35: Beban Penyusutan dan Amortisasi | D35: 14925.662 | E35: 17302.446 | F35: 5939.5001 | G35: =IFERROR((F35/E35)*100,"") | H35: =IFERROR((F35/D35)*100,"")
C36: Jumlah Beban Usaha | D36: 147950.07 | E36: 176531.42 | F36: 63649.986 | G36: =IFERROR((F36/E36)*100,"") | H36: =IFERROR((F36/D36)*100,"")
G37: =IFERROR((F37/E37)*100,"") | H37: =IFERROR((F37/D37)*100,"")
C38: LABA USAHA | D38: 212416.6 | E38: 211918.34 | F38: 100738.15 | G38: =IFERROR((F38/E38)*100,"") | H38: =IFERROR((F38/D38)*100,"")
E39: 0 | G39: =IFERROR((F39/E39)*100,"") | H39: =IFERROR((F39/D39)*100,"")
C40: PENDAPATAN (BEBAN) LAIN-LAIN | D40: -21683.627 | E40: -19963.356 | F40: -7929.3815 | G40: =IFERROR((F40/E40)*100,"") | H40: =IFERROR((F40/D40)*100,"")
G41: =IFERROR((F41/E41)*100,"") | H41: =IFERROR((F41/D41)*100,"")
...

Sheet Lap. PK - Kinerja Mei 2026
B1: PT JAMINAN PEMBIAYAAN ASKRINDO SYARIAH
B2: LAPORAN POSISI KEUANGAN
B3: Per 31 Mei 2026
F4: (Jutaan Rp)
B5: URAIAN | C5: Realisasi per 31 Des 25 (Audited) | D5: Anggaran 2026 | E5: Realisasi per 31 Mei 2026 | F5: Rasio (%)
B7: 1 | C7: 2 | D7: 3 | E7: 4 | F7: 5 (4:3) | G7: 6 (4:2)
B9: ASET
B11: Kas dan bank | C11: 23869.903 | D11: 20924 | E11: 30559.128 | F11: 146.05076 | G11: 128.02368
B12: Deposito berjangka untuk tujuan tertentu | C12: 50000 | D12: 100000 | E12: 50000 | F12: 50 | G12: 100 | I12: Account Rec
B13: Piutang imbal jasa kafalah | C13: 3541.4689 | D13: 2960 | E13: 1967.8546 | F13: 66.48971 | G13: 55.566057 | I13: Allowance for doubtufull account
B14: Piutang imbal jasa kafalah - CKPN | C14: -1626.9139 | D14: - | E14: -1626.9139 | F14: 0 | G14: 100 | I14: receivable - claim recovery
B15: Piutang tawidh | C15: 61619.994 | D15: 56683 | E15: 83612.495 | F15: 147.50928 | G15: 135.69053
B16: Piutang tawidh - CKPN | C16: -899.86309 | D16: - | E16: -899.86309 | F16: 0 | G16: 100
B17: Piutang investasi | C17: 27279.873 | D17: 31921 | E17: 34642.715 | F17: 108.52525 | G17: 126.99001 | I17: Accrued interest
B18: Aset Reas | C18: 647000.06 | D18: 847155 | E18: 649442.41 | F18: 76.661553 | G18: 100.37749
B19: Biaya akuisisi yang ditangguhkan | C19: 36128.885 | D19: 37638 | E19: 37495.456 | F19: 99.620373 | G19: 103.78249 | I19: prepaid
B20: Biaya dibayar dimuka | C20: 829.737 | D20: 11889 | E20: 15767.556 | F20: 132.62599 | G20: 1900.3077 | I20: prepaid
B21: Pajak dibayar dimuka | C21: 1.9073486e-11 | D21: - | E21: 1.9073486e-11 | F21: 0 | G21: 100
B22: Investasi | F22: 0 | G22: 0
B23: Deposito | C23: 563600 | D23: 454400 | E23: 434550 | F23: 95.631602 | G23: 77.102555
B24: Reksadana | C24: 50557.501 | D24: 142247 | E24: 110811.71 | F24: 77.901093 | G24: 219.17956
B25: Surat Berharga Syariah Negara | C25: 1761634.6 | D25: 2034234 | E25: 1919962.9 | F25: 94.382601 | G25: 108.98758
B26: Aset pajak tangguhan | C26: 22839.203 | D26: 13873 | E26: 22839.203 | F26: 164.63536 | G26: 100 | I26: deferred tax
B27: Aset tetap | C27: 28516.272 | D27: 26434 | E27: 26367.793 | F27: 99.749663 | G27: 92.465778
B28: Aset tidak berwujud | C28: 2255.2848 | D28: 6638 | E28: 1846.8591 | F28: 27.824372 | G28: 81.890284
B29: Aset lain-lain | C29: 1859.6554 | D29: 3452 | E29: 1606.8143 | F29: 46.544745 | G29: 86.403873
F30: 0 | G30: 0
B31: JUMLAH ASET | C31: 3279005.7 | D31: 3790447 | E31: 3418946.1 | F31: 90.199027 | G31: 104.26777
F32: 0 | G32: 0
B33: LIABILITAS DAN EKUITAS | F33: 0 | G33: 0
F34: 0 | G34: 0
B35: Utang tawidh | C35: 213.8093 | D35: 2146 | E35: 45.282592 | F35: 2.1101507 | G35: 21.178963
B36: Utang penjaminan ulang | C36: 33327.255 | D36: 50513 | E36: 51394.471 | F36: 101.74542 | G36: 154.21153
B37: Utang Komisi | C37: 7948.4533 | D37: 9136 | E37: 7665.0231 | F37: 83.894887 | G37: 96.434146 | I37: accrued liabilities
B38: Pendapatan diterima dimuka | C38: 31210.445 | D38: 31937 | E38: 27201.735 | F38: 85.17255 | G38: 87.155871 | I38: unearned revenue
B39: Utang zakat | C39: 6303.2957 | D39: 7513 | E39: 5186.8036 | F39: 69.036098 | G39: 82.287169
B40: Utang pajak | C40: 10054.8 | D40: 18698 | E40: 13717.441 | F40: 73.362894 | G40: 136.42678
B41: Beban akrual | C41: 40672.599 | D41: 62693 | E41: 45895.602 | F41: 73.206413 | G41: 112.84158 | I41: Accrued Liabilities
B42: Estimasi tawidh retensi sendiri | C42: 437877.2 | D42: 657950 | E42: 459364.96 | F42: 69.817573 | G42: 104.90726 | I42: Allowance/claims reserve
B43: Estimasi IJK YBMP | C43: 1402018.4 | D43: 1502201 | E43: 1465819.5 | F43: 97.578103 | G43: 104.55066
...

Sheet Lap. AK-Kinerja Mei 2026
B2: PT JAMINAN PEMBIAYAAN ASKRINDO SYARIAH
B3: LAPORAN ARUS KAS
B4: Periode 1 Januari s.d 31 Mei 2026
F5: (Jutaan Rp)
B6: URAIAN | C6: Realisasi s.d 31 Des 2025 (Audited) | D6: Anggaran Tahun 2026 | E6: Realisasi s.d 31 Mei 2026 | F6: Rasio (%)
B8: 1 | C8: 2 | D8: 3 | E8: 4 | F8: 5 (4:3) | G8: 6 (4:2)
B10: A.Saldo Awal Bulan (Tahun) | C10: 103869.27 | D10: 99508 | E10: 73869.903 | F10: 74.235087 | G10: 71.118148
B12: B.Penerimaan
B13: 1.Penerimaan Pokok
B14: - Imbal jasa kafalah | C14: 836483.69 | D14: 901614 | E14: 402640.18 | F14: 44.6577 | G14: 48.134851
B15: - Recoveries | C15: 83357.094 | D15: 59838 | E15: 23867.007 | F15: 39.885741 | G15: 28.632245
B16: - Tawidh Reas | C16: 160839.24 | D16: 172490 | E16: 54607.115 | F16: 31.65813 | G16: 33.477876
F17: 0 | G17: 0
F18: 0 | G18: 0
B19: Jumlah | C19: 1080680 | D19: 1133943 | E19: 481114.3 | F19: 42.428449 | G19: 44.426073
F20: 0 | G20: 0
F21: 0 | G21: 0
B22: 2.Hasil Investasi | C22: 151151.23 | D22: 157862 | E22: 55193.493 | F22: 34.963176 | G22: 36.515411
B23: 3. Tambahan Modal Disetor | C23: 0 | D23: - | E23: 0 | F23: 0 | G23: 0
B24: 4. Penerimaan Kafalah Lain | C24: 127.52209 | D24: 136 | E24: 39.633552 | F24: 29.12051 | G24: 31.079755
B25: 5.Penerimaan Lain-Lain | C25: 836.04339 | D25: 1006 | E25: 1547.6639 | F25: 153.85435 | G25: 142.90244
F26: 0 | G26: 0
F27: 0 | G27: 0
B28: Jumlah Penerimaan | C28: 1232794.8 | D28: 1292947 | E28: 537895.09 | F28: 41.602269 | G28: 43.543096
F29: 0 | G29: 0
F30: 0 | G30: 0
F31: 0 | G31: 0
B32: C.Pengeluaran | F32: 0 | G32: 0
B33: 1. Beban Kafalah | F33: 0 | G33: 0
B34: - Ta'widh | C34: 561199.63 | D34: 532403 | E34: 238716.92 | F34: 44.837666 | G34: 42.536899
B35: - Biaya Akuisisi | C35: 26407.318 | D35: 28445 | E35: 12851.728 | F35: 45.181031 | G35: 48.667298
B36: - Beban Penjaminan Ulang | C36: 158270.99 | D36: 179704 | E36: 55677.546 | F36: 30.982886 | G36: 34.680166
B37: - Beban Kafalah lain | C37: 2980.3344 | D37: 3299 | E37: 835.13356 | F37: 25.31318 | G37: 28.021471
F38: 0 | G38: 0
F39: 0 | G39: 0
B40: Jumlah | C40: 748858.27 | D40: 743851 | E40: 308081.33 | F40: 41.417075 | G40: 41.015546
F41: 0 | G41: 0
F42: 0 | G42: 0
F43: 0 | G43: 0
B44: 2. Beban Usaha | F44: 0 | G44: 0
...

Sheet Beban Usaha
G1: Dalam Juta Rupiah
B2: K E T E R A N G A N | G2: Realisasi s.d Mei 25 | H2: Realisasi s.d Des 25 (Audited) | I2: RKAP 2026 | J2: Realisasi s.d April 26 | K2: Mutasi Mei 26 | L2: Realisasi s.d Mei 26 | M2: Rasio (%)
B3: 1 | G3: 2 (INPUT) | H3: 3 | I3: 4 | J3: 5 (INPUT) | K3: 6 | L3: 7 (INPUT) | M3: 8 (7/4) | N3: 9 (7/2)
B4: A. | C4: BEBAN PEMASARAN | G4: 4712.1651 | H4: 13136.563 | I4: 14704.226 | J4: 4349.7301 | K4: =L4-J4 | L4: 5562.0003 | M4: =IF(I4=0,0,$K4/I4*100) | N4: =IF(G4=0,0,$K4/G4*100)
B5: B. | C5: BEBAN UMUM | G5: 39671.097 | H5: 99161.776 | I5: 120237.58 | J5: 34312.458 | K5: =L5-J5 | L5: 44696.839 | M5: =IF(I5=0,0,$K5/I5*100) | N5: =IF(G5=0,0,$K5/G5*100)
B6: C. | C6: BEBAN ADMINISTRASI | G6: 7210.0197 | H6: 20726.068 | I6: 24287.176 | J6: 5846.7861 | K6: =L6-J6 | L6: 7451.6472 | M6: =IF(I6=0,0,$K6/I6*100) | N6: =IF(G6=0,0,$K6/G6*100)
B7: D. | C7: BEBAN PENYUSUTAN DAN AMORTISASI | G7: 6389.3085 | H7: 14925.662 | I7: 17302.446 | J7: 4728.0455 | K7: =L7-J7 | L7: 5939.5001 | M7: =IF(I7=0,0,$K7/I7*100) | N7: =IF(G7=0,0,$K7/G7*100)
B8: J U M L A H | G8: 57982.591 | H8: 147950.07 | I8: 176531.42 | J8: 49237.019 | K8: =L8-J8 | L8: 63649.986 | M8: =IF(I8=0,0,$K8/I8*100) | N8: =IF(G8=0,0,$K8/G8*100)
B10: A. | C10: BEBAN PEMASARAN
C12: 1. | D12: P R O M O S I | G12: 228.32 | H12: 1111.8233 | I12: 1058.7285 | J12: 202.05 | K12: =L12-J12 | L12: 262.05 | M12: =IF(I12=0,0,$K12/I12*100) | N12: =IF(G12=0,0,$K12/G12*100)
C13: 2. | D13: PERJALANAN DINAS | G13: 0 | H13: 0 | I13: 0 | J13: 0 | K13: =L13-J13 | L13: 0 | M13: =IF(I13=0,0,$K13/I13*100) | N13: =IF(G13=0,0,$K13/G13*100)
C14: 3. | D14: BEBAN RAPAT | G14: 101.68257 | H14: 387.79836 | I14: 1709.617 | J14: 79.005393 | K14: =L14-J14 | L14: 324.49264 | M14: =IF(I14=0,0,$K14/I14*100) | N14: =IF(G14=0,0,$K14/G14*100)
C15: 4. | D15: ENTERTAINMENT DAN REPRESENTASI | G15: 3769.4746 | H15: 10610.822 | I15: 10318.417 | J15: 3875.0516 | K15: =L15-J15 | L15: 4718.3219 | M15: =IF(I15=0,0,$K15/I15*100) | N15: =IF(G15=0,0,$K15/G15*100)
C16: 5. | D16: MERCHANDISE | G16: 12 | H16: 42.127762 | I16: 123.23834 | J16: 0 | K16: =L16-J16 | L16: 0 | M16: =IF(I16=0,0,$K16/I16*100) | N16: =IF(G16=0,0,$K16/G16*100)
C17: 6. | D17: RAKER | G17: 389.22631 | H17: 689.83891 | I17: 1035.2811 | J17: 187.12309 | K17: =L17-J17 | L17: 250.63574 | M17: =IF(I17=0,0,$K17/I17*100) | N17: =IF(G17=0,0,$K17/G17*100)
C18: 7. | D18: REWARD ACHIVEMENT | G18: 211.4616 | H18: 294.15194 | I18: 458.94402 | J18: 6.5 | K18: =L18-J18 | L18: 6.5 | M18: =IF(I18=0,0,$K18/I18*100) | N18: =IF(G18=0,0,$K18/G18*100)
B20: TOTAL A : BEBAN PEMASARAN | G20: 4712.1651 | H20: 13136.563 | I20: 14704.226 | J20: 4349.7301 | K20: =L20-J20 | L20: 5562.0003 | M20: =IF(I20=0,0,$K20/I20*100) | N20: =IF(G20=0,0,$K20/G20*100)
B22: B. | C22: BEBAN UMUM
C23: 1. | D23: BEBAN PEGAWAI
D24: 1.1. | E24: Gaji/Honor Dewan Pengawas Syariah | G24: 117.42 | H24: 316.32 | I24: 409.032 | J24: 102.6 | K24: =L24-J24 | L24: 136.8 | M24: =IF(I24=0,0,$K24/I24*100) | N24: =IF(G24=0,0,$K24/G24*100)
D25: 1.2. | E25: Gaji/Honor Dewan Komisaris | G25: 1123.9405 | H25: 2894.3362 | I25: 3304 | J25: 922.66192 | K25: =L25-J25 | L25: 1201.5619 | M25: =IF(I25=0,0,$K25/I25*100) | N25: =IF(G25=0,0,$K25/G25*100)
D26: 1.3. | E26: Take Home Pay Direksi | G26: 1720.406 | H26: 4631.5926 | I26: 4932.72 | J26: 1426.477 | K26: =L26-J26 | L26: 1850.777 | M26: =IF(I26=0,0,$K26/I26*100) | N26: =IF(G26=0,0,$K26/G26*100)
D27: 1.4. | E27: Gaji Pegawai | G27: 13421.734 | H27: 34555.545 | I27: 37922.72 | J27: 11458.961 | K27: =L27-J27 | L27: 14665.461 | M27: =IF(I27=0,0,$K27/I27*100) | N27: =IF(G27=0,0,$K27/G27*100)
D28: 1.5. | E28: Honor Outsourcing | G28: 2488.1728 | H28: 7022.576 | I28: 5244.4213 | J28: 2377.7073 | K28: =L28-J28 | L28: 3019.3502 | M28: =IF(I28=0,0,$K28/I28*100) | N28: =IF(G28=0,0,$K28/G28*100)
D29: 1.6. | E29: L e m b u r | G29: 59.254864 | H29: 132.21304 | I29: 101.29585 | J29: 16.215046 | K29: =L29-J29 | L29: 20.295401 | M29: =IF(I29=0,0,$K29/I29*100) | N29: =IF(G29=0,0,$K29/G29*100)
D30: 1.7. | E30: Tunjangan - Tunjangan
E31: 1.7.1. | F31: Hari Raya | G31: 2616.3702 | H31: 6382.4406 | I31: 6829.21 | J31: 2215.6025 | K31: =L31-J31 | L31: 2784.7033 | M31: =IF(I31=0,0,$K31/I31*100) | N31: =IF(G31=0,0,$K31/G31*100)
E32: 1.7.2. | F32: Bantuan Pendidikan | G32: 1145.11 | H32: 2864.4599 | I32: 2796.8036 | J32: 932.26785 | K32: =L32-J32 | L32: 1165.3348 | M32: =IF(I32=0,0,$K32/I32*100) | N32: =IF(G32=0,0,$K32/G32*100)
E33: 1.7.3. | F33: Bantuan Qurban | G33: 0 | H33: 0 | J33: 0 | K33: =L33-J33 | L33: 0 | M33: =IF(I33=0,0,$K33/I33*100) | N33: =IF(G33=0,0,$K33/G33*100)
E34: 1.7.4. | F34: Zakat Pegawai | G34: 0 | H34: 0 | J34: 0 | K34: =L34-J34 | L34: 0 | M34: =IF(I34=0,0,$K34/I34*100) | N34: =IF(G34=0,0,$K34/G34*100)
E35: 1.7.5. | F35: Pajak Pasal 21 | G35: 2924.6343 | H35: 7483.0684 | I35: 10212.807 | J35: 1454.7054 | K35: =L35-J35 | L35: 2420.0054 | M35: =IF(I35=0,0,$K35/I35*100) | N35: =IF(G35=0,0,$K35/G35*100)
E36: 1.7.6. | F36: Cuti | G36: 1739.6598 | H36: 3121.8632 | I36: 3665.8629 | J36: 1637.0125 | K36: =L36-J36 | L36: 1958.3042 | M36: =IF(I36=0,0,$K36/I36*100) | N36: =IF(G36=0,0,$K36/G36*100)
E37: Sub Jumlah Tunjangan-Tunjangan | G37: 8425.7742 | H37: 19851.832 | I37: 23504.683 | J37: 6239.5883 | K37: =L37-J37 | L37: 8328.3477 | M37: =IF(I37=0,0,$K37/I37*100) | N37: =IF(G37=0,0,$K37/G37*100)
D39: 1.8. | E39: Kesejahteraan Pegawai
E40: 1.8.1. | F40: Premi Asuransi Pensiun & THT | G40: 1815.5925 | H40: 1765.0926 | I40: 4167.9761 | J40: 917.00039 | K40: =L40-J40 | L40: 1298.2004 | M40: =IF(I40=0,0,$K40/I40*100) | N40: =IF(G40=0,0,$K40/G40*100)
